2025-02-02 13:26:55,155 - src.data.data_loader - ERROR - [data_loader.py:31] - Error loading JSON file 'data/evaluation/evaluation_set_grouping.jsonl': File does not exist.
2025-02-02 13:26:55,187 - src.data.data_loader - ERROR - [data_loader.py:31] - Error loading JSON file 'data/input/queries_theme.json': File does not exist.
2025-02-03 18:10:49,095 - pipeline.pipeline_runner - ERROR - [pipeline_runner.py:73] - Error creating Elasticsearch BM25 index 'contextual_bm25_index_standard_quotation': Failed to connect to Elasticsearch at http://localhost:9200
Traceback (most recent call last):
  File "/Users/amankumarshrestha/Documents/GitHub/Thematic-AnalysisG/src/pipeline/pipeline_runner.py", line 65, in create_elasticsearch_bm25_index
    es_bm25 = ElasticsearchBM25(index_name=index_name)
              ^^^^^^^^^^^^^^^^^^^^^^^^^^^^^^^^^^^^^^^^
  File "/Users/amankumarshrestha/Documents/GitHub/Thematic-AnalysisG/src/core/elasticsearch_bm25.py", line 30, in __init__
    raise ConnectionError(f"Failed to connect to Elasticsearch at {es_host}")
ConnectionError: Failed to connect to Elasticsearch at http://localhost:9200
2025-02-03 18:10:49,096 - pipeline.pipeline_runner - ERROR - [pipeline_runner.py:168] - Error in pipeline execution for enhancedquotation: Failed to connect to Elasticsearch at http://localhost:9200
Traceback (most recent call last):
  File "/Users/amankumarshrestha/Documents/GitHub/Thematic-AnalysisG/src/pipeline/pipeline_runner.py", line 121, in run_pipeline_with_config
    self.es_bm25 = self.create_elasticsearch_bm25_index(config.index_name)
                   ^^^^^^^^^^^^^^^^^^^^^^^^^^^^^^^^^^^^^^^^^^^^^^^^^^^^^^^
  File "/Users/amankumarshrestha/Documents/GitHub/Thematic-AnalysisG/src/pipeline/pipeline_runner.py", line 65, in create_elasticsearch_bm25_index
    es_bm25 = ElasticsearchBM25(index_name=index_name)
              ^^^^^^^^^^^^^^^^^^^^^^^^^^^^^^^^^^^^^^^^
  File "/Users/amankumarshrestha/Documents/GitHub/Thematic-AnalysisG/src/core/elasticsearch_bm25.py", line 30, in __init__
    raise ConnectionError(f"Failed to connect to Elasticsearch at {es_host}")
ConnectionError: Failed to connect to Elasticsearch at http://localhost:9200
2025-02-03 18:10:49,096 - pipeline.pipeline_runner - ERROR - [pipeline_runner.py:229] - Pipeline execution failed: Failed to connect to Elasticsearch at http://localhost:9200
Traceback (most recent call last):
  File "/Users/amankumarshrestha/Documents/GitHub/Thematic-AnalysisG/src/pipeline/pipeline_runner.py", line 205, in run_pipeline
    await self.run_pipeline_with_config(config, optimizer_config)
  File "/Users/amankumarshrestha/Documents/GitHub/Thematic-AnalysisG/src/pipeline/pipeline_runner.py", line 121, in run_pipeline_with_config
    self.es_bm25 = self.create_elasticsearch_bm25_index(config.index_name)
                   ^^^^^^^^^^^^^^^^^^^^^^^^^^^^^^^^^^^^^^^^^^^^^^^^^^^^^^^
  File "/Users/amankumarshrestha/Documents/GitHub/Thematic-AnalysisG/src/pipeline/pipeline_runner.py", line 65, in create_elasticsearch_bm25_index
    es_bm25 = ElasticsearchBM25(index_name=index_name)
              ^^^^^^^^^^^^^^^^^^^^^^^^^^^^^^^^^^^^^^^^
  File "/Users/amankumarshrestha/Documents/GitHub/Thematic-AnalysisG/src/core/elasticsearch_bm25.py", line 30, in __init__
    raise ConnectionError(f"Failed to connect to Elasticsearch at {es_host}")
ConnectionError: Failed to connect to Elasticsearch at http://localhost:9200
2025-02-03 18:10:49,190 - __main__ - CRITICAL - [main.py:94] - Pipeline execution failed: Failed to connect to Elasticsearch at http://localhost:9200
Traceback (most recent call last):
  File "/Users/amankumarshrestha/Documents/GitHub/Thematic-AnalysisG/src/main.py", line 91, in <module>
    asyncio.run(pipeline.run_pipeline(configs))
  File "/opt/homebrew/Cellar/python@3.12/3.12.8/Frameworks/Python.framework/Versions/3.12/lib/python3.12/asyncio/runners.py", line 194, in run
    return runner.run(main)
           ^^^^^^^^^^^^^^^^
  File "/opt/homebrew/Cellar/python@3.12/3.12.8/Frameworks/Python.framework/Versions/3.12/lib/python3.12/asyncio/runners.py", line 118, in run
    return self._loop.run_until_complete(task)
           ^^^^^^^^^^^^^^^^^^^^^^^^^^^^^^^^^^^
  File "/opt/homebrew/Cellar/python@3.12/3.12.8/Frameworks/Python.framework/Versions/3.12/lib/python3.12/asyncio/base_events.py", line 686, in run_until_complete
    return future.result()
           ^^^^^^^^^^^^^^^
  File "/Users/amankumarshrestha/Documents/GitHub/Thematic-AnalysisG/src/pipeline/pipeline_runner.py", line 205, in run_pipeline
    await self.run_pipeline_with_config(config, optimizer_config)
  File "/Users/amankumarshrestha/Documents/GitHub/Thematic-AnalysisG/src/pipeline/pipeline_runner.py", line 121, in run_pipeline_with_config
    self.es_bm25 = self.create_elasticsearch_bm25_index(config.index_name)
                   ^^^^^^^^^^^^^^^^^^^^^^^^^^^^^^^^^^^^^^^^^^^^^^^^^^^^^^^
  File "/Users/amankumarshrestha/Documents/GitHub/Thematic-AnalysisG/src/pipeline/pipeline_runner.py", line 65, in create_elasticsearch_bm25_index
    es_bm25 = ElasticsearchBM25(index_name=index_name)
              ^^^^^^^^^^^^^^^^^^^^^^^^^^^^^^^^^^^^^^^^
  File "/Users/amankumarshrestha/Documents/GitHub/Thematic-AnalysisG/src/core/elasticsearch_bm25.py", line 30, in __init__
    raise ConnectionError(f"Failed to connect to Elasticsearch at {es_host}")
ConnectionError: Failed to connect to Elasticsearch at http://localhost:9200
2025-02-03 18:11:28,756 - src.core.contextual_vector_db - ERROR - [contextual_vector_db.py:314] - Embeddings or metadata are not loaded. Cannot perform search.
2025-02-03 18:11:28,757 - src.core.contextual_vector_db - ERROR - [contextual_vector_db.py:314] - Embeddings or metadata are not loaded. Cannot perform search.
2025-02-03 18:11:28,757 - src.core.contextual_vector_db - ERROR - [contextual_vector_db.py:314] - Embeddings or metadata are not loaded. Cannot perform search.
2025-02-03 18:11:28,757 - src.core.contextual_vector_db - ERROR - [contextual_vector_db.py:314] - Embeddings or metadata are not loaded. Cannot perform search.
2025-02-03 18:11:28,757 - src.core.contextual_vector_db - ERROR - [contextual_vector_db.py:314] - Embeddings or metadata are not loaded. Cannot perform search.
2025-02-03 18:11:31,141 - src.core.contextual_vector_db - ERROR - [contextual_vector_db.py:314] - Embeddings or metadata are not loaded. Cannot perform search.
2025-02-03 18:11:31,142 - src.core.contextual_vector_db - ERROR - [contextual_vector_db.py:314] - Embeddings or metadata are not loaded. Cannot perform search.
2025-02-03 18:11:31,142 - src.core.contextual_vector_db - ERROR - [contextual_vector_db.py:314] - Embeddings or metadata are not loaded. Cannot perform search.
2025-02-03 18:11:31,142 - src.core.contextual_vector_db - ERROR - [contextual_vector_db.py:314] - Embeddings or metadata are not loaded. Cannot perform search.
2025-02-03 18:11:31,142 - src.core.contextual_vector_db - ERROR - [contextual_vector_db.py:314] - Embeddings or metadata are not loaded. Cannot perform search.
2025-02-03 18:11:31,142 - src.core.contextual_vector_db - ERROR - [contextual_vector_db.py:314] - Embeddings or metadata are not loaded. Cannot perform search.
2025-02-03 18:11:31,143 - src.core.contextual_vector_db - ERROR - [contextual_vector_db.py:314] - Embeddings or metadata are not loaded. Cannot perform search.
2025-02-03 18:11:31,143 - src.core.contextual_vector_db - ERROR - [contextual_vector_db.py:314] - Embeddings or metadata are not loaded. Cannot perform search.
2025-02-03 18:11:32,226 - src.core.contextual_vector_db - ERROR - [contextual_vector_db.py:314] - Embeddings or metadata are not loaded. Cannot perform search.
2025-02-03 18:11:32,272 - src.core.contextual_vector_db - ERROR - [contextual_vector_db.py:314] - Embeddings or metadata are not loaded. Cannot perform search.
2025-02-03 18:11:32,287 - src.core.contextual_vector_db - ERROR - [contextual_vector_db.py:314] - Embeddings or metadata are not loaded. Cannot perform search.
2025-02-03 18:11:32,308 - src.core.contextual_vector_db - ERROR - [contextual_vector_db.py:314] - Embeddings or metadata are not loaded. Cannot perform search.
2025-02-03 18:11:32,326 - src.core.contextual_vector_db - ERROR - [contextual_vector_db.py:314] - Embeddings or metadata are not loaded. Cannot perform search.
2025-02-03 18:11:33,958 - src.core.contextual_vector_db - ERROR - [contextual_vector_db.py:314] - Embeddings or metadata are not loaded. Cannot perform search.
2025-02-03 18:11:33,958 - src.core.contextual_vector_db - ERROR - [contextual_vector_db.py:314] - Embeddings or metadata are not loaded. Cannot perform search.
2025-02-03 18:11:33,958 - src.core.contextual_vector_db - ERROR - [contextual_vector_db.py:314] - Embeddings or metadata are not loaded. Cannot perform search.
2025-02-03 18:11:33,959 - src.core.contextual_vector_db - ERROR - [contextual_vector_db.py:314] - Embeddings or metadata are not loaded. Cannot perform search.
2025-02-03 18:11:33,959 - src.core.contextual_vector_db - ERROR - [contextual_vector_db.py:314] - Embeddings or metadata are not loaded. Cannot perform search.
2025-02-03 18:11:33,959 - src.core.contextual_vector_db - ERROR - [contextual_vector_db.py:314] - Embeddings or metadata are not loaded. Cannot perform search.
2025-02-03 18:11:33,959 - src.core.contextual_vector_db - ERROR - [contextual_vector_db.py:314] - Embeddings or metadata are not loaded. Cannot perform search.
2025-02-03 18:11:33,959 - src.core.contextual_vector_db - ERROR - [contextual_vector_db.py:314] - Embeddings or metadata are not loaded. Cannot perform search.
2025-02-03 18:11:34,852 - src.core.contextual_vector_db - ERROR - [contextual_vector_db.py:314] - Embeddings or metadata are not loaded. Cannot perform search.
2025-02-03 18:11:34,871 - src.core.contextual_vector_db - ERROR - [contextual_vector_db.py:314] - Embeddings or metadata are not loaded. Cannot perform search.
2025-02-03 18:11:34,886 - src.core.contextual_vector_db - ERROR - [contextual_vector_db.py:314] - Embeddings or metadata are not loaded. Cannot perform search.
2025-02-03 18:11:34,910 - src.core.contextual_vector_db - ERROR - [contextual_vector_db.py:314] - Embeddings or metadata are not loaded. Cannot perform search.
2025-02-03 18:11:34,932 - src.core.contextual_vector_db - ERROR - [contextual_vector_db.py:314] - Embeddings or metadata are not loaded. Cannot perform search.
2025-02-03 18:11:36,551 - src.data.data_loader - ERROR - [data_loader.py:31] - Error loading JSON file 'data/evaluation/evaluation_set_grouping.jsonl': File does not exist.
